Workbook

Sheet Read Me
A1: Fiix permissions reference
A2: Compiled from the Fiix Help Center permission library on 2026-10-02. Default settings only.
A4: What this is | B4: A searchable copy of the default Fiix user group permissions plus every documented dependency between permissions. Use it to see what each default group can do and what has to be switched on together. Scoped to Fiix v5. Content that only exists in v6 is on the grey 'v6 Reference (not v5)' tab and is excluded everywhere else.
A5: How v5 works | B5: Permissions live only on user groups. Go to Settings > User Groups, open a group, and use its Menu, Page, Purchasing and API permission tabs. There are no system roles in v5, because user groups do that job. The fifth layer, role permissions, is v6 only.
A6: What it is not | B6: It does not show YOUR tenant's settings. Any group you have edited or created will differ. Fiix's own API can export your actual groups, which is a good next check.
A7: Default groups | B7: Guests, Logistics, Manager, Purchasing, Technician, Admin. Source tables abbreviate these as Guest, Log., Mgr., Purch., Tech., Admin.
A8: Sheets
A9: Summary | B9: Counts per group, calculated live from the sheets below with formulas.
A10: Page Permissions | B10: Every page and sub-permission with the default groups that get it. Filter by group or page.
A11: Menu Permissions | B11: Left navigation items per default group.
A12: Purchasing Permissions | B12: Purchase order workflow steps per default group.
A13: API Permissions | B13: Per Fiix class: A=Add, F=Find, C=Change, R=Remove. These class names are the same ones the Fiix API accepts as className.
A14: Dependencies | B14: Every documented prerequisite, one row per link, plus general rules about how the permission types fit together.
A15: Dependency Tree | B15: The same links drawn as an indented tree. Each permission sits under its deepest prerequisite; any others are in 'Also requires'.
A16: Feature Permissions (v5) | B16: Descriptions of asset, scheduled maintenance, v5 work order and user management permissions.
A17: v6 Reference (not v5) | B17: System role and v6 work order permissions. Does not apply to a v5 tenant.
A18: Cautions
A19: Version is per feature | B19: Fiix rolls v6 out feature by feature, so Work Orders and User Management can each be v5 or v6. Fiix's two 'Which version am I using' articles show how to tell: Maintenance > Work Orders, and Settings > Users.
A20: Help Center how-to is v6 | B20: Fiix's step-by-step user group articles, including 'Basic setup: Permissions, users groups, and roles', are written for v6. For v5, use 'About permissions' and this workbook.
A21: Source quirk: seats handler | B21: The user management permissions article calls 'User Increase Tenant Seats - UI handler' defunct. Fiix's v5/v6 comparison still lists it as a requirement for changing user status. Both are shown.
A22: API in v5 | B22: Fiix says v5 tenants can reach all tables in the API reference, and that API access is Enterprise only.
A23: Source quirk: Technician menu | B23: The default menu table shows Technicians WITHOUT the Work Orders and Assigned Work Orders menu items, while the default user groups article says Technicians can see work orders. Verify in your tenant.
A24: Source quirk: blank page name | B24: One row in the page permissions table, 'Has Transfer stock button', has a blank page name in the source. It sits directly after Stock, so it is listed there and marked.
A25: Dependencies are partial | B25: Fiix documents prerequisites for system roles, v6 work orders, assets, scheduled maintenance and user status. Other pages have none published, which does not prove none exist.
A26: Wording | B26: Descriptions are lightly condensed from the Help Center text. Check the linked article for the authoritative wording.
A27: Derived columns | B27: 'Page type' on Page Permissions and 'Level' on Menu Permissions were added here, not taken from Fiix. List page = has a New button. Detail page = has a Save button.
A29: Sources
A30: Article | B30: URL
A31: About permissions | B31: https://helpdesk.fiixsoftware.com/hc/en-us/articles/360049317472-About-permissions
A32: About default user groups | B32: https://helpdesk.fiixsoftware.com/hc/en-us/articles/18165584633876-About-default-user-groups
A33: Which version of User Management am I using? | B33: https://helpdesk.fiixsoftware.com/hc/en-us/articles/13012571221396-Which-version-of-User-Management-am-I-using
A34: Which version of Work Orders am I using? | B34: https://helpdesk.fiixsoftware.com/hc/en-us/articles/7884592276756-Which-version-of-Work-Orders-am-I-using
A35: Compare user management v5 and v6 features | B35: https://helpdesk.fiixsoftware.com/hc/en-us/articles/21769760933652-Compare-user-management-v5-and-v6-features
A36: Default user group permissions - page permissions | B36: https://helpdesk.fiixsoftware.com/hc/en-us/articles/360049275232-Default-user-group-permissions-page-permissions
A37: Default user group permissions - menu permissions | B37: https://helpdesk.fiixsoftware.com/hc/en-us/articles/360049707091-Default-user-group-permissions-menu-permissions
A38: Default user group permissions - purchasing | B38: https://helpdesk.fiixsoftware.com/hc/en-us/articles/360049317492-Default-user-group-permissions-purchasing
A39: Default user group permissions - API permissions | B39: https://helpdesk.fiixsoftware.com/hc/en-us/articles/360049795251-Default-user-group-permissions-API-permissions
A40: Work orders permissions (v5) | B40: https://helpdesk.fiixsoftware.com/hc/en-us/articles/40598772915988-Work-orders-permissions
A41: Asset permissions | B41: https://helpdesk.fiixsoftware.com/hc/en-us/articles/42176625317652-Asset-permissions
... A46: [v6 only] Work orders permissions (v6) | B46: https://helpdesk.fiixsoftware.com/hc/en-us/articles/27945783675924-Work-orders-permissions-v6

Sheet Summary
A1: Default permissions per group
A2: All numbers are formulas over the other sheets. They update if you edit those sheets.
A4: Group | B4: Menu permissions | C4: Page permissions | D4: Purchasing permissions | E4: Total granted | F4: Share of all page permissions
A5: Guests | B5: =COUNTIF('Menu Permissions'!C2:C54,"✓") -> 1 | C5: =COUNTIF('Page Permissions'!C2:C475,"✓") -> 4 | D5: =COUNTIF('Purchasing Permissions'!C2:C14,"✓") -> 0 | E5: =SUM(B5:D5) -> 5 | F5: =C5/$C$11 -> 0.0084388186
A6: Logistics | B6: =COUNTIF('Menu Permissions'!D2:D54,"✓") -> 22 | C6: =COUNTIF('Page Permissions'!D2:D475,"✓") -> 239 | D6: =COUNTIF('Purchasing Permissions'!D2:D14,"✓") -> 13 | E6: =SUM(B6:D6) -> 274 | F6: =C6/$C$11 -> 0.50421941
A7: Manager | B7: =COUNTIF('Menu Permissions'!E2:E54,"✓") -> 34 | C7: =COUNTIF('Page Permissions'!E2:E475,"✓") -> 364 | D7: =COUNTIF('Purchasing Permissions'!E2:E14,"✓") -> 0 | E7: =SUM(B7:D7) -> 398 | F7: =C7/$C$11 -> 0.76793249
A8: Purchasing | B8: =COUNTIF('Menu Permissions'!F2:F54,"✓") -> 15 | C8: =COUNTIF('Page Permissions'!F2:F475,"✓") -> 141 | D8: =COUNTIF('Purchasing Permissions'!F2:F14,"✓") -> 13 | E8: =SUM(B8:D8) -> 169 | F8: =C8/$C$11 -> 0.29746835
A9: Technician | B9: =COUNTIF('Menu Permissions'!G2:G54,"✓") -> 13 | C9: =COUNTIF('Page Permissions'!G2:G475,"✓") -> 162 | D9: =COUNTIF('Purchasing Permissions'!G2:G14,"✓") -> 0 | E9: =SUM(B9:D9) -> 175 | F9: =C9/$C$11 -> 0.34177215
A10: Admin | B10: =COUNTIF('Menu Permissions'!H2:H54,"✓") -> 53 | C10: =COUNTIF('Page Permissions'!H2:H475,"✓") -> 474 | D10: =COUNTIF('Purchasing Permissions'!H2:H14,"✓") -> 13 | E10: =SUM(B10:D10) -> 540 | F10: =C10/$C$11 -> 1
A11: Total available | B11: =COUNTA('Menu Permissions'!A2:A54) -> 53 | C11: =COUNTA('Page Permissions'!B2:B475) -> 474 | D11: =COUNTA('Purchasing Permissions'!B2:B14) -> 13 | E11: =SUM(B11:D11) -> 540
A15: API access per group (Fiix classes)
A16: Group | B16: Classes with any access | C16: Classes with Find | D16: Classes with any write (Add, Change or Remove) | E16: Classes with full access | F16: Total classes
A17: Administrators | B17: =COUNTIF('API Permissions'!B2:B72,"<>-") -> 71 | C17: =COUNTIF('API Permissions'!B2:B72,"*F*") -> 71 | D17: =SUMPRODUCT(--((ISNUMBER(SEARCH("A",'API Permissions'!B2:B72))+ISNUMBER(SEARCH("C",'API Permissions'!B2:B72))+ISNUMBER(SEARCH("R",'API Permissions'!B2:B72)))>0)) -> 71 | E17: =COUNTIF('API Permissions'!B2:B72,"AFCR") -> 71 | F17: =COUNTA('API Permissions'!A2:A72) -> 71
A18: Managers | B18: =COUNTIF('API Permissions'!C2:C72,"<>-") -> 56 | C18: =COUNTIF('API Permissions'!C2:C72,"*F*") -> 56 | D18: =SUMPRODUCT(--((ISNUMBER(SEARCH("A",'API Permissions'!C2:C72))+ISNUMBER(SEARCH("C",'API Permissions'!C2:C72))+ISNUMBER(SEARCH("R",'API Permissions'!C2:C72)))>0)) -> 27 | E18: =COUNTIF('API Permissions'!C2:C72,"AFCR") -> 12 | F18: =COUNTA('API Permissions'!A2:A72) -> 71
A19: Technicians | B19: =COUNTIF('API Permissions'!D2:D72,"<>-") -> 46 | C19: =COUNTIF('API Permissions'!D2:D72,"*F*") -> 46 | D19: =SUMPRODUCT(--((ISNUMBER(SEARCH("A",'API Permissions'!D2:D72))+ISNUMBER(SEARCH("C",'API Permissions'!D2:D72))+ISNUMBER(SEARCH("R",'API Permissions'!D2:D72)))>0)) -> 11 | E19: =COUNTIF('API Permissions'!D2:D72,"AFCR") -> 6 | F19: =COUNTA('API Permissions'!A2:A72) -> 71
A20: Purchasing | B20: =COUNTIF('API Permissions'!E2:E72,"<>-") -> 28 | C20: =COUNTIF('API Permissions'!E2:E72,"*F*") -> 28 | D20: =SUMPRODUCT(--((ISNUMBER(SEARCH("A",'API Permissions'!E2:E72))+ISNUMBER(SEARCH("C",'API Permissions'!E2:E72))+ISNUMBER(SEARCH("R",'API Permissions'!E2:E72)))>0)) -> 5 | E20: =COUNTIF('API Permissions'!E2:E72,"AFCR") -> 4 | F20: =COUNTA('API Permissions'!A2:A72) -> 71
A21: Logistics | B21: =COUNTIF('API Permissions'!F2:F72,"<>-") -> 39 | C21: =COUNTIF('API Permissions'!F2:F72,"*F*") -> 39 | D21: =SUMPRODUCT(--((ISNUMBER(SEARCH("A",'API Permissions'!F2:F72))+ISNUMBER(SEARCH("C",'API Permissions'!F2:F72))+ISNUMBER(SEARCH("R",'API Permissions'!F2:F72)))>0)) -> 12 | E21: =COUNTIF('API Permissions'!F2:F72,"AFCR") -> 6 | F21: =COUNTA('API Permissions'!A2:A72) -> 71
A23: Guests have no API permissions and are not listed.

Sheet Page Permissions
A1: Page | B1: Permission | C1: Guests | D1: Logistics | E1: Manager | F1: Purchasing | G1: Technician | H1: Admin | I1: Groups granted | J1: Page type
A2: Add To Open Purchase Order | B2: Can Access | D2: ✓ | F2: ✓ | H2: ✓ | I2: =COUNTIF(C2:H2,"✓") -> 3 | J2: List page
A3: Add To Open Purchase Order | B3: Has 'New' Button | D3: ✓ | F3: ✓ | H3: ✓ | I3: =COUNTIF(C3:H3,"✓") -> 3 | J3: List page
A4: Add To Open Purchase Order | B4: Has 'Edit' Menu Item | D4: ✓ | F4: ✓ | H4: ✓ | I4: =COUNTIF(C4:H4,"✓") -> 3 | J4: List page
A5: Add To Open Purchase Order | B5: Has 'Print' Button | D5: ✓ | F5: ✓ | H5: ✓ | I5: =COUNTIF(C5:H5,"✓") -> 3 | J5: List page
A6: Add To Open Purchase Order | B6: Has 'Delete' Button | D6: ✓ | F6: ✓ | H6: ✓ | I6: =COUNTIF(C6:H6,"✓") -> 3 | J6: List page
A7: Add To Open Purchase Order | B7: Has 'Export' Button | D7: ✓ | F7: ✓ | H7: ✓ | I7: =COUNTIF(C7:H7,"✓") -> 3 | J7: List page
A8: Add To Open Purchase Order | B8: Has 'Import' Button | D8: ✓ | F8: ✓ | H8: ✓ | I8: =COUNTIF(C8:H8,"✓") -> 3 | J8: List page
A9: Add to Open RFQ | B9: Can Access | D9: ✓ | F9: ✓ | H9: ✓ | I9: =COUNTIF(C9:H9,"✓") -> 3 | J9: List page
A10: Add to Open RFQ | B10: Has 'New' Button | D10: ✓ | F10: ✓ | H10: ✓ | I10: =COUNTIF(C10:H10,"✓") -> 3 | J10: List page
A11: Add to Open RFQ | B11: Has 'Edit' Menu Item | D11: ✓ | F11: ✓ | H11: ✓ | I11: =COUNTIF(C11:H11,"✓") -> 3 | J11: List page
A12: Add to Open RFQ | B12: Has 'Print' Button | D12: ✓ | F12: ✓ | H12: ✓ | I12: =COUNTIF(C12:H12,"✓") -> 3 | J12: List page
A13: Add to Open RFQ | B13: Has 'Delete' Button | D13: ✓ | F13: ✓ | H13: ✓ | I13: =COUNTIF(C13:H13,"✓") -> 3 | J13: List page
... A15: Add to Open RFQ | B15: Has 'Import' Button | D15: ✓ | F15: ✓ | H15: ✓ | I15: =COUNTIF(C15:H15,"✓") -> 3 | J15: List page
A16: Asset Business | B16: Can Access | D16: ✓ | E16: ✓ | F16: ✓ | G16: ✓ | H16: ✓ | I16: =COUNTIF(C16:H16,"✓") -> 5 | J16: Detail page
A17: Asset Business | B17: Has 'Save' Button | D17: ✓ | E17: ✓ | F17: ✓ | H17: ✓ | I17: =COUNTIF(C17:H17,"✓") -> 4 | J17: Detail page
A18: Asset Business | B18: Has 'Print' Button | D18: ✓ | E18: ✓ | F18: ✓ | G18: ✓ | H18: ✓ | I18: =COUNTIF(C18:H18,"✓") -> 5 | J18: Detail page
A19: Asset Business | B19: Has 'Import' Button | D19: ✓ | E19: ✓ | F19: ✓ | H19: ✓ | I19: =COUNTIF(C19:H19,"✓") -> 4 | J19: Detail page
A20: Asset | B20: Can Access | D20: ✓ | E20: ✓ | G20: ✓ | H20: ✓ | I20: =COUNTIF(C20:H20,"✓") -> 4 | J20: Detail page
A21: Asset | B21: Has 'Save' Button | D21: ✓ | E21: ✓ | H21: ✓ | I21: =COUNTIF(C21:H21,"✓") -> 3 | J21: Detail page
A22: Asset | B22: Has 'Print' Button | D22: ✓ | E22: ✓ | G22: ✓ | H22: ✓ | I22: =COUNTIF(C22:H22,"✓") -> 4 | J22: Detail page
A23: Asset | B23: Has 'Import' Button | D23: ✓ | E23: ✓ | H23: ✓ | I23: =COUNTIF(C23:H23,"✓") -> 3 | J23: Detail page
A24: Asset Categories | B24: Can Access | H24: ✓ | I24: =COUNTIF(C24:H24,"✓") -> 1 | J24: List page
A25: Asset Categories | B25: Has 'New' Button | H25: ✓ | I25: =COUNTIF(C25:H25,"✓") -> 1 | J25: List page
A26: Asset Categories | B26: Has 'Edit' Menu Item | H26: ✓ | I26: =COUNTIF(C26:H26,"✓") -> 1 | J26: List page
A27: Asset Categories | B27: Has 'Print' Button | H27: ✓ | I27: =COUNTIF(C27:H27,"✓") -> 1 | J27: List page
A28: Asset Categories | B28: Has 'Delete' Button | H28: ✓ | I28: =COUNTIF(C28:H28,"✓") -> 1 | J28: List page
A29: Asset Categories | B29: Has 'Export' Button | H29: ✓ | I29: =COUNTIF(C29:H29,"✓") -> 1 | J29: List page
A30: Asset Categories | B30: Has 'Import' Button | H30: ✓ | I30: =COUNTIF(C30:H30,"✓") -> 1 | J30: List page
A31: Asset Category | B31: Can Access | H31: ✓ | I31: =COUNTIF(C31:H31,"✓") -> 1 | J31: Detail page
A32: Asset Category | B32: Has 'Save' Button | H32: ✓ | I32: =COUNTIF(C32:H32,"✓") -> 1 | J32: Detail page
A33: Asset Category | B33: Has 'Print' Button | H33: ✓ | I33: =COUNTIF(C33:H33,"✓") -> 1 | J33: Detail page
A34: Asset Category | B34: Has 'Import' Button | H34: ✓ | I34: =COUNTIF(C34:H34,"✓") -> 1 | J34: Detail page
A35: Asset Event | B35: Can Access | D35: ✓ | E35: ✓ | G35: ✓ | H35: ✓ | I35: =COUNTIF(C35:H35,"✓") -> 4 | J35: Detail page
A36: Asset Event | B36: Has 'Save' Button | D36: ✓ | E36: ✓ | G36: ✓ | H36: ✓ | I36: =COUNTIF(C36:H36,"✓") -> 4 | J36: Detail page
A37: Asset Event | B37: Has 'Print' Button | D37: ✓ | E37: ✓ | G37: ✓ | H37: ✓ | I37: =COUNTIF(C37:H37,"✓") -> 4 | J37: Detail page
A38: Asset Event | B38: Has 'Import' Button | D38: ✓ | E38: ✓ | G38: ✓ | H38: ✓ | I38: =COUNTIF(C38:H38,"✓") -> 4 | J38: Detail page
A39: Asset Events History | B39: Can Access | E39: ✓ | G39: ✓ | H39: ✓ | I39: =COUNTIF(C39:H39,"✓") -> 3 | J39: Detail page
A40: Asset Events History | B40: Has 'Save' Button | E40: ✓ | G40: ✓ | H40: ✓ | I40: =COUNTIF(C40:H40,"✓") -> 3 | J40: Detail page
A41: Asset Events History | B41: Has 'Print' Button | E41: ✓ | G41: ✓ | H41: ✓ | I41: =COUNTIF(C41:H41,"✓") -> 3 | J41: Detail page
...

Sheet Menu Permissions
A1: Permission | B1: Level | C1: Guests | D1: Logistics | E1: Manager | F1: Purchasing | G1: Technician | H1: Admin | I1: Groups granted
A2: Can See 'Settings' Top Menu | B2: Top menu | H2: ✓ | I2: =COUNTIF(C2:H2,"✓") -> 1
A3: Can See 'Users' Menu Item | B3: Menu item | H3: ✓ | I3: =COUNTIF(C3:H3,"✓") -> 1
A4: Can See 'User Groups' Menu Item | B4: Menu item | H4: ✓ | I4: =COUNTIF(C4:H4,"✓") -> 1
A5: Can See 'Business' Menu Item | B5: Menu item | H5: ✓ | I5: =COUNTIF(C5:H5,"✓") -> 1
A6: Can See 'Import' Menu Item | B6: Menu item | H6: ✓ | I6: =COUNTIF(C6:H6,"✓") -> 1
A7: Can See 'Cmms Settings' Menu Item | B7: Menu item | H7: ✓ | I7: =COUNTIF(C7:H7,"✓") -> 1
A8: Can See 'Account Settings' Menu Item | B8: Menu item | H8: ✓ | I8: =COUNTIF(C8:H8,"✓") -> 1
A9: Can See 'Notification Templates' Menu Item | B9: Menu item | H9: ✓ | I9: =COUNTIF(C9:H9,"✓") -> 1
A10: Can See 'Connect Management' Menu Item | B10: Menu item | H10: ✓ | I10: =COUNTIF(C10:H10,"✓") -> 1
A11: Can See 'Data Dictionary' Menu Item | B11: Menu item | H11: ✓ | I11: =COUNTIF(C11:H11,"✓") -> 1
A12: Can See 'Localization' Menu Item | B12: Menu item | H12: ✓ | I12: =COUNTIF(C12:H12,"✓") -> 1
A13: Can See 'Audit Log' Menu Item | B13: Menu item | H13: ✓ | I13: =COUNTIF(C13:H13,"✓") -> 1
... A15: Can See 'Security And Infrastructure' Menu Item | B15: Menu item | H15: ✓ | I15: =COUNTIF(C15:H15,"✓") -> 1
A16: Can See 'Help' Top Menu | B16: Top menu | D16: ✓ | E16: ✓ | F16: ✓ | G16: ✓ | H16: ✓ | I16: =COUNTIF(C16:H16,"✓") -> 5
A17: Can See 'Log Off' Top Menu | B17: Top menu | D17: ✓ | E17: ✓ | F17: ✓ | G17: ✓ | H17: ✓ | I17: =COUNTIF(C17:H17,"✓") -> 5
A18: Can See 'Dashboard' Top Menu | B18: Top menu | D18: ✓ | E18: ✓ | F18: ✓ | G18: ✓ | H18: ✓ | I18: =COUNTIF(C18:H18,"✓") -> 5
A19: Can See 'Dashboard' Menu Item | B19: Menu item | D19: ✓ | E19: ✓ | F19: ✓ | G19: ✓ | H19: ✓ | I19: =COUNTIF(C19:H19,"✓") -> 5
A20: Can See 'Calendar' Menu Item | B20: Menu item | E20: ✓ | G20: ✓ | H20: ✓ | I20: =COUNTIF(C20:H20,"✓") -> 3
A21: Can See 'Assigned Assets' Menu Item | B21: Menu item | E21: ✓ | H21: ✓ | I21: =COUNTIF(C21:H21,"✓") -> 2
A22: Can See 'Assigned Work Orders' Menu Item | B22: Menu item | E22: ✓ | H22: ✓ | I22: =COUNTIF(C22:H22,"✓") -> 2
A23: Can See 'Submit Work Request' Menu Item | B23: Menu item | C23: ✓ | D23: ✓ | E23: ✓ | G23: ✓ | H23: ✓ | I23: =COUNTIF(C23:H23,"✓") -> 5
A24: Can See 'My Purchase Requests' Menu Item | B24: Menu item | D24: ✓ | E24: ✓ | F24: ✓ | G24: ✓ | H24: ✓ | I24: =COUNTIF(C24:H24,"✓") -> 5
A25: Can See 'Submit Purchase Request' Menu Item | B25: Menu item | D25: ✓ | E25: ✓ | F25: ✓ | G25: ✓ | H25: ✓ | I25: =COUNTIF(C25:H25,"✓") -> 5
A26: Can See 'Maintenance' Top Menu | B26: Top menu | E26: ✓ | H26: ✓ | I26: =COUNTIF(C26:H26,"✓") -> 2
A27: Can See 'Work Orders' Menu Item | B27: Menu item | E27: ✓ | H27: ✓ | I27: =COUNTIF(C27:H27,"✓") -> 2
A28: Can See 'Scheduled Maintenance' Menu Item | B28: Menu item | E28: ✓ | H28: ✓ | I28: =COUNTIF(C28:H28,"✓") -> 2
A29: Can See 'Task Groups' Menu Item | B29: Menu item | E29: ✓ | H29: ✓ | I29: =COUNTIF(C29:H29,"✓") -> 2
A30: Can See 'Projects' Menu Item | B30: Menu item | E30: ✓ | H30: ✓ | I30: =COUNTIF(C30:H30,"✓") -> 2
A31: Can See 'Notifications' Top Menu | B31: Top menu | D31: ✓ | E31: ✓ | F31: ✓ | G31: ✓ | H31: ✓ | I31: =COUNTIF(C31:H31,"✓") -> 5
A32: Can See 'Inbox' Menu Item | B32: Menu item | D32: ✓ | E32: ✓ | F32: ✓ | G32: ✓ | H32: ✓ | I32: =COUNTIF(C32:H32,"✓") -> 5
A33: Can See 'Sent' Menu Item | B33: Menu item | D33: ✓ | E33: ✓ | F33: ✓ | G33: ✓ | H33: ✓ | I33: =COUNTIF(C33:H33,"✓") -> 5
A34: Can See 'System Messages' Menu Item | B34: Menu item | D34: ✓ | E34: ✓ | F34: ✓ | G34: ✓ | H34: ✓ | I34: =COUNTIF(C34:H34,"✓") -> 5
A35: Can See 'Trash' Menu Item | B35: Menu item | D35: ✓ | E35: ✓ | F35: ✓ | G35: ✓ | H35: ✓ | I35: =COUNTIF(C35:H35,"✓") -> 5
A36: Can See 'Assets' Top Menu | B36: Top menu | E36: ✓ | H36: ✓ | I36: =COUNTIF(C36:H36,"✓") -> 2
A37: Can See 'All Assets' Menu Item | B37: Menu item | E37: ✓ | H37: ✓ | I37: =COUNTIF(C37:H37,"✓") -> 2
A38: Can See 'Facilities' Menu Item | B38: Menu item | E38: ✓ | H38: ✓ | I38: =COUNTIF(C38:H38,"✓") -> 2
A39: Can See 'Equipment' Menu Item | B39: Menu item | E39: ✓ | H39: ✓ | I39: =COUNTIF(C39:H39,"✓") -> 2
A40: Can See 'Tools' Menu Item | B40: Menu item | E40: ✓ | H40: ✓ | I40: =COUNTIF(C40:H40,"✓") -> 2
A41: Can See 'Supplies' Top Menu | B41: Top menu | D41: ✓ | E41: ✓ | H41: ✓ | I41: =COUNTIF(C41:H41,"✓") -> 3
...

Sheet Purchasing Permissions
A1: PO status | B1: Permission | C1: Guests | D1: Logistics | E1: Manager | F1: Purchasing | G1: Technician | H1: Admin | I1: Groups granted
A2: Draft | B2: Can Submit for Approval | D2: ✓ | F2: ✓ | H2: ✓ | I2: =COUNTIF(C2:H2,"✓") -> 3
A3: Draft | B3: Can Send to Supplier | D3: ✓ | F3: ✓ | H3: ✓ | I3: =COUNTIF(C3:H3,"✓") -> 3
A4: Draft | B4: Can Cancel Purchase Order | D4: ✓ | F4: ✓ | H4: ✓ | I4: =COUNTIF(C4:H4,"✓") -> 3
A5: Waiting for Approval | B5: Can Approve Purchase Order | D5: ✓ | F5: ✓ | H5: ✓ | I5: =COUNTIF(C5:H5,"✓") -> 3
A6: Waiting for Approval | B6: Can Reject Purchase Order | D6: ✓ | F6: ✓ | H6: ✓ | I6: =COUNTIF(C6:H6,"✓") -> 3
A7: Waiting for Approval | B7: Can Cancel Purchase Order | D7: ✓ | F7: ✓ | H7: ✓ | I7: =COUNTIF(C7:H7,"✓") -> 3
A8: Approved | B8: Can Send to Supplier | D8: ✓ | F8: ✓ | H8: ✓ | I8: =COUNTIF(C8:H8,"✓") -> 3
A9: Approved | B9: Can Cancel Purchase Order | D9: ✓ | F9: ✓ | H9: ✓ | I9: =COUNTIF(C9:H9,"✓") -> 3
A10: On Order | B10: Can Send to Supplier | D10: ✓ | F10: ✓ | H10: ✓ | I10: =COUNTIF(C10:H10,"✓") -> 3
A11: On Order | B11: Can Set to Order Not Fulfilled | D11: ✓ | F11: ✓ | H11: ✓ | I11: =COUNTIF(C11:H11,"✓") -> 3
A12: On Order | B12: Can Cancel Purchase Order | D12: ✓ | F12: ✓ | H12: ✓ | I12: =COUNTIF(C12:H12,"✓") -> 3
A13: Order Fulfilled | B13: Can Back to Draft | D13: ✓ | F13: ✓ | H13: ✓ | I13: =COUNTIF(C13:H13,"✓") -> 3
A14: Order Not Fulfilled | B14: Can Back to Draft | D14: ✓ | F14: ✓ | H14: ✓ | I14: =COUNTIF(C14:H14,"✓") -> 3

Sheet API Permissions
A1: Fiix class | B1: Administrators | C1: Managers | D1: Technicians | E1: Purchasing | F1: Logistics | G1: Groups with any access
A2: Account | B2: AFCR | C2: F | D2: F | E2: - | F2: F | G2: =COUNTIF(B2:F2,"<>-") -> 4
A3: Asset | B3: AFCR | C3: AFCR | D3: F | E3: F | F3: AFCR | G3: =COUNTIF(B3:F3,"<>-") -> 5
A4: AssetBusiness | B4: AFCR | C4: AFC | D4: F | E4: AFC | F4: AFC | G4: =COUNTIF(B4:F4,"<>-") -> 5
A5: AssetCategory | B5: AFCR | C5: F | D5: F | E5: F | F5: F | G5: =COUNTIF(B5:F5,"<>-") -> 5
A6: AssetConsumingReference | B6: AFCR | C6: AFC | D6: - | E6: - | F6: AFC | G6: =COUNTIF(B6:F6,"<>-") -> 3
A7: AssetEvent | B7: AFCR | C7: AFCR | D7: AFCR | E7: - | F7: FC | G7: =COUNTIF(B7:F7,"<>-") -> 4
A8: AssetEventType | B8: AFCR | C8: F | D8: F | E8: - | F8: F | G8: =COUNTIF(B8:F8,"<>-") -> 4
A9: AssetEventTypeAsset | B9: AFCR | C9: F | D9: F | E9: - | F9: F | G9: =COUNTIF(B9:F9,"<>-") -> 4
A10: AssetOfflineTracker | B10: AFCR | C10: - | D10: - | E10: - | F10: - | G10: =COUNTIF(B10:F10,"<>-") -> 1
A11: AssetUser | B11: AFCR | C11: AFC | D11: AFC | E11: - | F11: AFC | G11: =COUNTIF(B11:F11,"<>-") -> 4
A12: BillingTerm | B12: AFCR | C12: - | D12: - | E12: - | F12: - | G12: =COUNTIF(B12:F12,"<>-") -> 1
A13: Business | B13: AFCR | C13: AFR | D13: - | E13: F | F13: AFR | G13: =COUNTIF(B13:F13,"<>-") -> 4
... A72: WorkOrderUser | B72: AFCR | C72: AFCR | D72: FR | E72: - | F72: - | G72: =COUNTIF(B72:F72,"<>-") -> 3
A74: Key
A75: A = Add (create) F = Find (read) C = Change (edit) R = Remove (delete) - = no access
A76: Guests have no API permissions. Green = full access, amber = partial, grey = none.
A77: Class names are the same values you pass as className in the Fiix API (see fiix-api/fiix_query.py).

Sheet Dependencies
A1: Area | B1: Permission | C1: Requires | D1: How enforced | E1: Source article
A2: User management (v5) | B2: Feature: Open Settings > Users and User Groups (view only) | C2: Users (page) | D2: Must also be granted | E2: Compare user management v5 and v6 features (v5 column, Access rows)
A3: User management (v5) | B3: Feature: Open Settings > Users and User Groups (view only) | C3: Can see 'Settings' top menu (menu) | D3: Must also be granted | E3: Compare user management v5 and v6 features (v5 column, Access rows)
A4: User management (v5) | B4: Feature: Select visible elements on the user list | C4: Can see 'Settings' top menu (menu) | D4: Must also be granted | E4: Compare user management v5 and v6 features (v5 column, Access rows)
A5: User management (v5) | B5: Feature: Select visible elements on the user list | C5: User Interface Customization Settings (page) | D5: Must also be granted | E5: Compare user management v5 and v6 features (v5 column, Access rows)
A6: User management (v5) | B6: Feature: Select visible elements on the user list | C6: Users (page) | D6: Must also be granted | E6: Compare user management v5 and v6 features (v5 column, Access rows)
A7: User management (v5) | B7: Feature: Export user list | C7: Can see 'Settings' top menu (menu) | D7: Must also be granted | E7: Compare user management v5 and v6 features (v5 column, Access rows)
A8: User management (v5) | B8: Feature: Export user list | C8: Users (page) | D8: Must also be granted | E8: Compare user management v5 and v6 features (v5 column, Access rows)
A9: User management (v5) | B9: Feature: Import users from CSV | C9: Can see 'Settings' top menu (menu) | D9: Must also be granted | E9: Compare user management v5 and v6 features (v5 column, Access rows)
A10: User management (v5) | B10: Feature: Import users from CSV | C10: Users (page) | D10: Must also be granted | E10: Compare user management v5 and v6 features (v5 column, Access rows)
A11: User management (v5) | B11: Feature: Import users from CSV | C11: Import Users From CSV File (page) | D11: Must also be granted | E11: Compare user management v5 and v6 features (v5 column, Access rows)
A12: User management (v5) | B12: Feature: Show last login date | C12: Can see 'Settings' top menu (menu) | D12: Must also be granted | E12: Compare user management v5 and v6 features (v5 column, Access rows)
... A63: General rule | B63: Mobile app / API access | C63: API permissions (Add / Find / Change / Remove per class) | D63: Both required | E63: About permissions

Sheet Dependency Tree
A1: Area | B1: Permission (indented = depends on the one above) | C1: Also requires | D1: How enforced
A2: Assets (v5) | B2: Asset (page)
A3: Assets (v5) | B3: └─ Asset Event Types (page) | C3: CMMS Settings (page) | D3: Must also be granted
A4: Assets (v5) | B4: Assets (page)
A5: Assets (v5) | B5: └─ Asset Business (page) | C5: Asset (page) | D5: Must also be granted
A6: Assets (v5) | B6: └─ Asset Categories (page) | C6: CMMS Settings (page); Asset (page) | D6: Must also be granted
A7: Assets (v5) | B7: └─ Asset Category (page) | C7: CMMS Settings (page); Asset (page) | D7: Must also be granted
A8: Assets (v5) | B8: └─ Asset Event (page) | C8: CMMS Settings (page); Asset (page) | D8: Must also be granted
A9: Scheduled maintenance (v5) | B9: └─ Scheduled Maintenance Trigger (page) | C9: Scheduled Maintenance Details (page) | D9: Must also be granted
A10: Assets (v5) | B10: └─ Asset Events History (page) | C10: Asset (page) | D10: Must also be granted
A11: Assets (v5) | B11: └─ Asset File (page) | C11: Asset (page) | D11: Must also be granted
A12: Assets (v5) | B12: └─ Asset Filter (page) | D12: Must also be granted
A13: Assets (v5) | B13: └─ Asset Parts Supplies (page) | C13: Asset (page) | D13: Must also be granted
A14: Assets (v5) | B14: └─ Asset Tag List (page) | D14: Must also be granted
A15: Assets (v5) | B15: └─ Assigned Assets (page) | C15: Can See 'Assigned Assets' (menu); Asset (page) | D15: Must also be granted
A16: Scheduled maintenance (v5) | B16: Scheduled Maintenance Details (page)
A17: Scheduled maintenance (v5) | B17: └─ Scheduled Maintenance File (page) | D17: Must also be granted
A18: Scheduled maintenance (v5) | B18: └─ Scheduled Parts (page) | D18: Must also be granted
A19: Scheduled maintenance (v5) | B19: └─ Scheduled Task (page) | D19: Must also be granted
A20: Scheduled maintenance (v5) | B20: └─ Scheduled Trigger Change Threshold (page) | D20: Must also be granted
A21: Scheduled maintenance (v5) | B21: Scheduled Maintenance List (page)
A22: Scheduled maintenance (v5) | B22: └─ Import Scheduled Maintenance (page) | C22: Can See Import Menu Item (menu) | D22: Must also be granted
A23: Scheduled maintenance (v5) | B23: └─ Import Task Groups (page) | C23: Can See Import Menu Item (menu) | D23: Must also be granted
A24: Scheduled maintenance (v5) | B24: └─ Scheduled Maintenance Filter (page) | D24: Must also be granted
A25: User management (v5) | B25: Can see 'Settings' top menu (menu)
A26: User management (v5) | B26: └─ Feature: Export user list | C26: Users (page) | D26: Must also be granted
A27: User management (v5) | B27: └─ Feature: Import users from CSV | C27: Users (page); Import Users From CSV File (page) | D27: Must also be granted
A28: User management (v5) | B28: └─ Feature: Localization | C28: Can see 'Localization' menu item (menu); Languages (page) | D28: Must also be granted
A29: User management (v5) | B29: └─ Feature: Open Settings > Users and User Groups (view only) | C29: Users (page) | D29: Must also be granted
A30: User management (v5) | B30: └─ Feature: Select visible elements on the user list | C30: User Interface Customization Settings (page); Users (page) | D30: Must also be granted
A31: User management (v5) | B31: └─ Feature: Show last login date | C31: Users (page); User Interface Customization Settings (page) | D31: Must also be granted
A32: User management (v5) | B32: User (page)
A33: User management (v5) | B33: └─ User Status (page) | D33: Must also be granted
A34: User management (v5) | B34: └─ Feature: Change user status | C34: Can see 'Settings' top menu (menu); Users (page); User (page); User Increase Tenant Seats - UI handler (page) | D34: Must also be granted

Sheet Feature Permissions (v5)
A1: Area | B1: Type | C1: Page / permission | D1: Sub-permissions | E1: What it allows | F1: Prerequisites | G1: Source article
A2: Work orders (v5) | B2: Menu | C2: Can see 'Maintenance' top menu item | E2: Allows users to see the Maintenance top menu item in the web app. | G2: Work orders permissions (v5)
A3: Work orders (v5) | B3: Menu | C3: Can see 'Work orders' menu item | E3: Allows the user to see Work orders menu item in the web app. | G3: Work orders permissions (v5)
A4: Work orders (v5) | B4: Menu | C4: Can see 'Task Groups' menu item | E4: Allows the user to see Task Groups menu item in the web app. | G4: Work orders permissions (v5)
A5: Work orders (v5) | B5: Page | C5: Work Orders Administration | D5: Can Access Has 'Save' Button Has 'Print' Button Can see 'Work Log' Info Can toggle 'Requires Signature' | E5: Allows the user permissions to act as manager or administrator of work orders in the web app and mobile app. Users with this permission can access all work orders in the mobile app (not just their own) as long as they have an internet connection, and perform manager-level actions in work orders on both platforms. Best for: users who act as managers or administrators of work orders. | G5: Work orders permissions (v5)
A6: Work orders (v5) | B6: Page | C6: Work Orders | D6: Can Access Has 'New' Button Has 'Print' Button Has 'Edit' Menu Item Has 'Update/Close Work Order' Menu Item Has 'Delete' Button Has 'Import' Button | E6: Allows the user to see and update work orders in the web app and the mobile app. | G6: Work orders permissions (v5)
A7: Work orders (v5) | B7: Page | C7: Work Order Assets | D7: Can Access Has 'New' Button Has 'Edit' Menu Button Has 'Print' Button Has 'Delete' Button Has 'Export' Button Has 'Import' Button | E7: Allows the user to add assets to work orders. | G7: Work orders permissions (v5)
A8: Work orders (v5) | B8: Page | C8: Work Order Business | D8: Can Access the 'Work Order Business' Has 'Save' Button Has 'Print' Button Has 'Import' Button | E8: Allows the user to add businesses to work orders. | G8: Work orders permissions (v5)
A9: Work orders (v5) | B9: Page | C9: Work Order Files | D9: Can Access Has 'Save' Button Has 'Print' Button Has 'Import' Button | E9: Allows the user to attach files to work orders. | G9: Work orders permissions (v5)
A10: Work orders (v5) | B10: Page | C10: Work Order Filters | D10: Can Access Has 'New' Button Has 'Edit' Menu Item Has 'Print' Button Has 'Delete' Button Has 'Export' Button Has 'Import' Button | E10: Allows the user to filter the work order list on the web app. | G10: Work orders permissions (v5)
A11: Work orders (v5) | B11: Page | C11: Work Order Parts | D11: Can Access Has 'Save' Button Has 'Print' Button Has 'Import' Button Has 'Delete' Button | E11: Allows the user to add and remove parts from work orders. | G11: Work orders permissions (v5)
A12: Work orders (v5) | B12: Page | C12: Work Order Status | D12: Can Access Has 'New' Button Has 'Edit' Menu Item Has 'Print' Button Has 'Delete' Button Has 'Export' Button Has 'Import' Button | E12: Allows the user to create new statuses, which can be assigned to work orders. | G12: Work orders permissions (v5)
A13: Work orders (v5) | B13: Page | C13: Work Order Task | D13: Can Access Has 'Save' Button Has 'Print' Button Has 'Import' Button | E13: Allows the user to add tasks to work orders. | G13: Work orders permissions (v5)
A14: Work orders (v5) | B14: Page | C14: Work Order User | D14: Can Access Has 'Save' Button Has 'Print' Button Has 'Import' Button | E14: Allows the user to assign users to work orders. Best for: users who manage other users, and who will be assigning other users to work orders. | G14: Work orders permissions (v5)
A15: Work orders (v5) | B15: Page | C15: Import Work Orders | D15: Can Access | E15: Allows the user to import work orders from a spreadsheet (Settings > Import > Import Work Orders). | G15: Work orders permissions (v5)
A16: Work orders (v5) | B16: Page | C16: Add Labor to Task | D16: Can Access Has 'Save' Button Has 'Print' Button Has 'Import' Button | E16: Allows the user to access Add Labor task completion notes window (Work order details page > Labor Tasks tab). | G16: Work orders permissions (v5)
A17: Work orders (v5) | B17: Page | C17: Add Task Group to WO | D17: Can Access Has 'New' Button Has 'Edit' Menu Item Has 'Print' Button Has 'Delete' Button Has 'Export' Button Has 'Import' Button | E17: Allows the user to add a task group to work orders. | G17: Work orders permissions (v5)
A18: Assets (v5) | B18: Menu | C18: Can see 'Assets' top menu | E18: Allows users to see the Assets top menu item in the web app. | G18: Asset permissions (v5)
A19: Assets (v5) | B19: Menu | C19: Can see 'Facilities' menu item | E19: Allows the user to see the Facilities menu item in the web app. | G19: Asset permissions (v5)
A20: Assets (v5) | B20: Menu | C20: Can see 'Equipment' menu item | E20: Allows the user to see the Equipment menu item in the web app. | G20: Asset permissions (v5)
A21: Assets (v5) | B21: Menu | C21: Can see 'Tools' menu item | E21: Allows the user to see the Tools menu item in the web app. | G21: Asset permissions (v5)
A22: Assets (v5) | B22: Menu | C22: Can see 'CMMS Settings' menu item | E22: Allows the user to access CMMS Settings in the web app. | G22: Asset permissions (v5)
A23: Assets (v5) | B23: Page | C23: Asset | D23: Can Access Has 'Save' Button Has 'Print' Button Has 'Import' Button | E23: Allows the user to see and edit individual assets and their detail pages, including setting the asset online or offline. | G23: Asset permissions (v5)
A24: Assets (v5) | B24: Page | C24: Assets | D24: Can Access Has 'New' Button Has 'Edit' Menu Item Has 'Print' Button Has 'Delete' Button Has 'Export' Button Has 'Import' Button | E24: Allows the user to access the list of assets. | G24: Asset permissions (v5)
A25: Assets (v5) | B25: Page | C25: Asset Business | D25: Can Access Has 'Save' Button Has 'Print' Button Has 'Import' Button | E25: Allows the user to add businesses to assets under the Business tab of the asset details page. | F25: Asset (page); Assets (page) | G25: Asset permissions (v5)
A26: Assets (v5) | B26: Page | C26: Asset Categories | D26: Can Access Has 'New' Button Has 'Edit' Menu Item Has 'Print' Button Has 'Delete' Button Has 'Export' Button Has 'Import' Button | E26: Allows the user to adjust how categories are organized in the asset hierarchy (which categories are parents and children of each other) and assign assets to categories in CMMS Settings > Asset Categories tab. | F26: CMMS Settings (page); Asset (page); Assets (page) | G26: Asset permissions (v5)
A27: Assets (v5) | B27: Page | C27: Asset Category | D27: Can Access Has 'Save' Button Has 'Print' Button Has 'Import' Button | E27: Allows the user to add new categories, edit asset category names, adjust category order in the hierarchy, and update barcode format for categories at CMMS Settings > Asset Categories tab. | F27: CMMS Settings (page); Asset (page); Assets (page) | G27: Asset permissions (v5)
A28: Assets (v5) | B28: Page | C28: Asset Event | D28: Can Access Has 'Save' Button Has 'Print' Button Has 'Import' Button | E28: Allows the user to add an asset event to an asset or a scheduled maintenance. Users with this permission can add asset events on the asset details page > Metering/Events tab > Most Recent Asset Events header > Add button. | F28: CMMS Settings (page); Asset (page); Assets (page) | G28: Asset permissions (v5)
A29: Assets (v5) | B29: Page | C29: Asset Event Types | D29: Can Access Has 'New' Button Has 'Edit' Menu Item Has 'Print' Button Has 'Delete' Button Has 'Export' Button Has 'Import' Button | E29: Expected behavior: Allows the user to add and edit event types at CMMS Settings > Lookup tables tab > Asset Event Types header. | F29: CMMS Settings (page); Asset (page) | G29: Asset permissions (v5)
A30: Assets (v5) | B30: Page | C30: Asset Events History | D30: Can Access Has 'Save' Button Has 'Print' Button Has 'Import' Button | E30: Allows the user to access the Asset Events History page, where the user can view and edit an asset's recorded asset events. To access the Asset Events History page, navigate to an asset details page > Metering/Events tab > Most Recent Asset Events header and click a recorded event. | F30: Asset (page); Assets (page) | G30: Asset permissions (v5)
A31: Assets (v5) | B31: Page | C31: Asset File | D31: Can Access Has 'Save' Has 'Print' Button Has 'Import' Button | E31: Allows the user to add and edit files to assets. Users without this permission can still add basic files to assets, but they can't change the file type. Users with this permission can click on an added file (Asset > Files tab) and change the file type, including add an asset default image. | F31: Asset (page); Assets (page) | G31: Asset permissions (v5)
A32: Assets (v5) | B32: Page | C32: Asset Filter | D32: Can Access Has 'Save' Button Has 'Print' Button Has 'Import' Button | E32: Expected behavior: Allows the user to use the list of filters on the asset list page, including adding and deleting the custom filters that are available to all users of the CMMS. | F32: Assets (page) | G32: Asset permissions (v5)
A33: Assets (v5) | B33: Page | C33: Asset Parts Supplies | D33: Can Access Has 'Save' Button Has 'Print' Button Has 'Import' Button | E33: Allows the user to add parts and supplies to an asset from the asset details page under the Parts/BOM tab. | F33: Asset (page); Assets (page) | G33: Asset permissions (v5)
A34: Assets (v5) | B34: Page | C34: Asset Tag List | D34: Can Access Has 'Save' Button Has 'Print' Button Has 'Import' Button | E34: Expected behavior: Allows the user to access the Print Asset Tag button on the assets list page to print labels for assets. | F34: Assets (page) | G34: Asset permissions (v5)
A35: Assets (v5) | B35: Page | C35: Assigned Assets | D35: Can Access Has 'New' Button Has 'Edit' Menu Item Has 'Print' Button Has 'Delete' Button Has 'Export' Button Has 'Import' Button | E35: Allows the user to access the Assigned Assets page, which shows assets assigned to the user and to their direct reports. | F35: Can See 'Assigned Assets' (menu); Asset (page); Assets (page) | G35: Asset permissions (v5)
A36: Assets (v5) | B36: Page | C36: Import Asset Event Types | D36: Can Access | E36: Allows the user to bulk import asset event types (Settings > Import > Asset Event Types). | G36: Asset permissions (v5)
A37: Assets (v5) | B37: Page | C37: Import Asset Events | D37: Can Access | E37: Allows the user to bulk import asset event types (Settings > Import > Asset Events). | G37: Asset permissions (v5)
A38: Assets (v5) | B38: Page | C38: Import Assets | D38: Can Access | E38: Allows the user to bulk import assets (Settings > Import > Asset Events). | G38: Asset permissions (v5)
A39: Scheduled maintenance (v5) | B39: Menu | C39: Can see 'Maintenance' top menu | E39: Allows users to see the Maintenance top menu item in the web app. | G39: Scheduled maintenance permissions (v5)
A40: Scheduled maintenance (v5) | B40: Menu | C40: Can see 'Scheduled Maintenance' menu item | E40: Allows the user to see the Scheduled Maintenance menu item in the web app. | G40: Scheduled maintenance permissions (v5)
...

Sheet v6 Reference (not v5)
A1: NOT APPLICABLE TO A v5 TENANT. System roles and v6 work order permissions only exist in Fiix v6. Kept for reference in case you move to v6.
A2: Area | B2: Permission | C2: What it allows | D2: Notes and prerequisites | E2: Source article
A3: System roles (v6) | B3: View users | C3: See users, their account details, and their access control pages. Permission is view-only. | E3: System role permissions (v6 User management)
A4: System roles (v6) | B4: View direct reports | C4: See account details of users that directly report to them only. Permission is view-only. | D4: Direct reports are users that have a manager assigned on their account details page. This permission gives view ability to the manager only, and they can only see their direct reports. | E4: System role permissions (v6 User management)
A5: System roles (v6) | B5: View user groups | C5: See all user groups and user group details, including permissions. Permission is view-only. | D5: Does not include viewing the users assigned to the user groups. | E5: System role permissions (v6 User management)
A6: System roles (v6) | B6: View system roles | C6: See all system roles and system role details, including permissions. Permission is view-only. | E6: System role permissions (v6 User management)
A7: System roles (v6) | B7: Create users | C7: Make new, inactive user accounts. New users won't take up a paid license (seat) until activated. This permission does not give activation privileges. | D7: Checking this permission will automatically check View users. | E7: System role permissions (v6 User management)
A8: System roles (v6) | B8: Create user groups | C8: Create new user groups and add descriptions. Can't edit user group permissions or assign users to the user group. | D8: Checking this permission will automatically check View user groups. | E8: System role permissions (v6 User management)
A9: System roles (v6) | B9: Create system roles | C9: Create new system roles and add descriptions. Can't edit permissions or assign users to system roles. | D9: Checking this permission will automatically check View system roles. | E9: System role permissions (v6 User management)
A10: System roles (v6) | B10: Edit users | C10: Make change to user details, including name, email address, and reset password. Assign users to user groups and system roles. In multi-site configurations: Add, edit, and manage regions, and assign users to regions and sites. | D10: Checking this permission will automatically check View users. | E10: System role permissions (v6 User management)
A11: System roles (v6) | B11: Edit user status | C11: Change user statuses to active, passive, or deactivated. Activating a user may send an account activation email and requires a license (seat). | D11: Checking this permission will automatically check View users. | E11: System role permissions (v6 User management)
A12: System roles (v6) | B12: Edit direct reports | C12: Make changes to user details, reset passwords, and deactivate their direct reports only. | D12: Direct reports are users that have a manager assigned on their account details page. This permission gives editing ability to the manager only, and they can only edit their direct reports. Checking this permission will automatically check View direct reports. | E12: System role permissions (v6 User management)
A13: System roles (v6) | B13: Edit user groups | C13: Make changes to user group names, descriptions, and permissions. | D13: Does not include editing which users are assigned to user groups (requires Edit Users). Checking this permission will automatically check View user groups. | E13: System role permissions (v6 User management)
A14: System roles (v6) | B14: Edit system roles | C14: Make changes to system role names, descriptions, and permissions. | D14: Does not include editing which users are assigned to the system role. Checking this permission will automatically check View system roles. | E14: System role permissions (v6 User management)
A15: System roles (v6) | B15: Delete user groups | C15: Permanently delete user groups. | D15: Checking this permission will automatically check View user groups. | E15: System role permissions (v6 User management)
A16: System roles (v6) | B16: Delete system roles | C16: Permanently delete system roles. | D16: Checking this permission will automatically check View system roles. | E16: System role permissions (v6 User management)
A17: Work orders (v6) | B17: View work orders and work order details | C17: See the work orders list in Maintenance > Work Orders and view a work order's details (including the content of all tabs). Permission is view-only. | E17: Work orders permissions (v6)
A18: Work orders (v6) | B18: Create work orders | C18: Create new work orders in Maintenance > Work Orders. This does not include editing work orders. | D18: Checking this permission will automatically check "View work orders and work order details". | E18: Work orders permissions (v6)
A19: Work orders (v6) | B19: Create tasks | C19: Create tasks from within a work order. This does not include editing tasks. | D19: Checking this permission will automatically check "View work orders and work order details". | E19: Work orders permissions (v6)
A20: Work orders (v6) | B20: Edit work order details | C20: Make changes to all fields on a work order, except Assign to User and Suggested start date and time. This does not include creating new work orders. | D20: Checking this permission will automatically check "View work orders and work order details". | E20: Work orders permissions (v6)
A21: Work orders (v6) | B21: Edit task details | C21: Make changes to all fields in a task, except Assigned to and Suggested start date and time. This does not include creating new tasks. | D21: Checking this permission will automatically check "View work orders and work order details". | E21: Work orders permissions (v6)
A22: Work orders (v6) | B22: Assign users or user groups to work orders | C22: Edit the Assign to User field in the Summary tab of a work order. | D22: Checking this permission will automatically check "View work orders and work order details" and "Edit work order details". | E22: Work orders permissions (v6)
A23: Work orders (v6) | B23: Assign users or user groups to tasks | C23: Use the Users slide-out panel accessible through the Actions menu > Assign on tasks in the task list. | D23: Checking this permission will automatically check "View work orders and work order details" and "Edit task details". | E23: Work orders permissions (v6)
A24: Work orders (v6) | B24: Set suggested start and completion dates for work orders | C24: Edit the Suggested start date and time field in the Summary tab of a work order. | D24: Checking this permission will automatically check "View work orders and work order details" and "Edit work order details". | E24: Work orders permissions (v6)
A25: Work orders (v6) | B25: Set suggested start date for tasks | C25: Edit the Suggested start date and time field on a task's details through the Actions menu > Edit. | D25: Checking this permission will automatically check "View work orders and work order details" and "Edit task details". | E25: Work orders permissions (v6)
A26: Work orders (v6) | B26: Delete work orders | C26: Delete any existing work orders. | D26: Checking this permission will automatically check "View work orders and work order details". | E26: Work orders permissions (v6)
A27: Work orders (v6) | B27: Delete tasks | C27: Delete any existing tasks on a work order. | D27: Checking this permission will automatically check "View work orders and work order details". | E27: Work orders permissions (v6)
